2019-02-28 02:30:10,403 POST http://127.0.0.1:11435/session {"capabilities": {"firstMatch": [{}], "alwaysMatch": {"browserName": "chrome", "platformName": "any", "goog:chromeOptions": {"extensions": [], "args": []}}}, "desiredCapabilities": {"browserName": "chrome", "version": "", "platform": "ANY", "goog:chromeOptions": {"extensions": [], "args": []}}}
2019-02-28 02:30:10,404 Starting new HTTP connection (1): 127.0.0.1:11435
2019-02-28 02:30:15,344 http://127.0.0.1:11435 "POST /session HTTP/1.1" 200 778
2019-02-28 02:30:15,345 Finished Request
2019-02-28 02:30:15,345 POST http://127.0.0.1:11435/session/edd6e51f210de51f8e90ada15b72baf1/url {"url": "https://s3.ap-northeast-2.amazonaws.com/mitchin/web/sign.html", "sessionId": "edd6e51f210de51f8e90ada15b72baf1"}
2019-02-28 02:30:15,346 Resetting dropped connection: 127.0.0.1
2019-02-28 02:30:17,053 http://127.0.0.1:11435 "POST /session/edd6e51f210de51f8e90ada15b72baf1/url HTTP/1.1" 200 347
2019-02-28 02:30:17,053 Finished Request
2019-02-28 02:30:17,053 Message: unknown error: cannot determine loading status
from unknown error: missing or invalid 'entry.level'
  (Session info: chrome=72.0.3626.119)
  (Driver info: chromedriver=2.29.461591 (62ebf098771772160f391d75e589dc567915b233),platform=Windows NT 10.0.16299 x86_64)
Traceback (most recent call last):
  File "c:\Users\Mark\Documents\Movie_DataMiner\IRP_ireland\IRP_parser.py", line 55, in TryToParse
    browser.get(url)
  File "C:\Users\Mark\Anaconda3\lib\site-packages\selenium\webdriver\remote\webdriver.py", line 333, in get
    self.execute(Command.GET, {'url': url})
  File "C:\Users\Mark\Anaconda3\lib\site-packages\selenium\webdriver\remote\webdriver.py", line 321, in execute
    self.error_handler.check_response(response)
  File "C:\Users\Mark\Anaconda3\lib\site-packages\selenium\webdriver\remote\errorhandler.py", line 242, in check_response
    raise exception_class(message, screen, stacktrace)
selenium.common.exceptions.WebDriverException: Message: unknown error: cannot determine loading status
from unknown error: missing or invalid 'entry.level'
  (Session info: chrome=72.0.3626.119)
  (Driver info: chromedriver=2.29.461591 (62ebf098771772160f391d75e589dc567915b233),platform=Windows NT 10.0.16299 x86_64)

2019-02-28 02:58:31,105 Message: 'chromedriver' executable needs to be in PATH. Please see https://sites.google.com/a/chromium.org/chromedriver/home
Traceback (most recent call last):
  File "C:\Users\Mark\Anaconda3\lib\site-packages\selenium\webdriver\common\service.py", line 76, in start
    stdin=PIPE)
  File "C:\Users\Mark\Anaconda3\lib\subprocess.py", line 756, in __init__
    restore_signals, start_new_session)
  File "C:\Users\Mark\Anaconda3\lib\subprocess.py", line 1155, in _execute_child
    startupinfo)
FileNotFoundError: [WinError 2] The system cannot find the file specified

During handling of the above exception, another exception occurred:

Traceback (most recent call last):
  File "c:/Users/Mark/Documents/Movie_DataMiner/IRP_ireland/IRP_parser.py", line 52, in TryToParse
    browser = webdriver.Chrome()
  File "C:\Users\Mark\Anaconda3\lib\site-packages\selenium\webdriver\chrome\webdriver.py", line 73, in __init__
    self.service.start()
  File "C:\Users\Mark\Anaconda3\lib\site-packages\selenium\webdriver\common\service.py", line 83, in start
    os.path.basename(self.path), self.start_error_message)
selenium.common.exceptions.WebDriverException: Message: 'chromedriver' executable needs to be in PATH. Please see https://sites.google.com/a/chromium.org/chromedriver/home

2019-10-01 18:27:01,888 Message: 'chromedriver' executable needs to be in PATH. Please see https://sites.google.com/a/chromium.org/chromedriver/home
Traceback (most recent call last):
  File "C:\Program Files (x86)\Microsoft Visual Studio\Shared\Python37_64\lib\site-packages\selenium\webdriver\common\service.py", line 76, in start
    stdin=PIPE)
  File "C:\Program Files (x86)\Microsoft Visual Studio\Shared\Python37_64\lib\subprocess.py", line 775, in __init__
    restore_signals, start_new_session)
  File "C:\Program Files (x86)\Microsoft Visual Studio\Shared\Python37_64\lib\subprocess.py", line 1178, in _execute_child
    startupinfo)
FileNotFoundError: [WinError 2] The system cannot find the file specified

During handling of the above exception, another exception occurred:

Traceback (most recent call last):
  File ".\workinghour.py", line 52, in TryToParse
    browser = webdriver.Chrome()
  File "C:\Program Files (x86)\Microsoft Visual Studio\Shared\Python37_64\lib\site-packages\selenium\webdriver\chrome\webdriver.py", line 73, in __init__
    self.service.start()
  File "C:\Program Files (x86)\Microsoft Visual Studio\Shared\Python37_64\lib\site-packages\selenium\webdriver\common\service.py", line 83, in start
    os.path.basename(self.path), self.start_error_message)
selenium.common.exceptions.WebDriverException: Message: 'chromedriver' executable needs to be in PATH. Please see https://sites.google.com/a/chromium.org/chromedriver/home

